Workbook

Sheet Report Configuration
A1: Configuration Options | B1: Your Google Analytics Reports
A2: Report Name | B2: LIB
A3: View ID | B3: 237444
A4: Start Date | B4: 30daysAgo
A5: End Date | B5: yesterday
A6: Metrics | B6: ga:users,ga:bounceRate,ga:impressions,ga:adClicks,ga:adCost,ga:pageviews
A7: Dimensions | B7: ga:sourceMedium,ga:date
A8: Order
A9: Filters | B9: ga:sourceMedium==google / cpc
A10: Segments
A11: Limit | B11: 1000
A12: Spreadsheet URL
A13: Skip Report
A14: Report Type
A15: Sampling Level
A16: Use Resource Quotas
A17: Exclude Empty Rows
B18: For help with this add-on: | C18: https://developers.google.com/analytics/solutions/google-analytics-spreadsheet-add-on

Sheet LIB
A1: LIB
A2: Last Run On | B2: 44064.264
A3: View Name | B3: www.libresse.ru
A4: Total Results Found | B4: 30
A5: Total Results Returned | B5: 30
A6: Contains Sampled Data | B6: No
A10: Totals For All Results
C11: Users | D11: Bounce Rate | E11: Impressions | F11: Clicks | G11: Cost | H11: Pageviews
C12: 34206 | D12: 0.8529148 | E12: 303073 | F12: 36559 | G12: 2788.6568 | H12: 47894
A14: Results Breakdown
A15: Source / Medium | B15: Date | C15: Users | D15: Bounce Rate | E15: Impressions | F15: Clicks | G15: Cost | H15: Pageviews
A16: google / cpc | B16: 44034 | C16: 34 | D16: 0.94444444 | E16: 0 | F16: 0 | G16: 0 | H16: 43
A17: google / cpc | B17: 44035 | C17: 939 | D17: 0.86395233 | E17: 8288 | F17: 978 | G17: 77.189121 | H17: 1275
A18: google / cpc | B18: 44036 | C18: 1675 | D18: 0.84430804 | E18: 13924 | F18: 1864 | G18: 135.71073 | H18: 2278
A19: google / cpc | B19: 44037 | C19: 1640 | D19: 0.86096866 | E19: 13748 | F19: 1783 | G19: 147.0287 | H19: 2275
A20: google / cpc | B20: 44038 | C20: 651 | D20: 0.86376404 | E20: 5028 | F20: 673 | G20: 51.349739 | H20: 883
A21: google / cpc | B21: 44039 | C21: 35 | D21: 0.8974359 | E21: 0 | F21: 0 | G21: 0 | H21: 101
A22: google / cpc | B22: 44040 | C22: 36 | D22: 0.97222222 | E22: 0 | F22: 0 | G22: 0 | H22: 38
A23: google / cpc | B23: 44041 | C23: 22 | D23: 0.95652174 | E23: 0 | F23: 0 | G23: 0 | H23: 24
A24: google / cpc | B24: 44042 | C24: 20 | D24: 0.95238095 | E24: 0 | F24: 0 | G24: 0 | H24: 22
A25: google / cpc | B25: 44043 | C25: 72 | D25: 0.825 | E25: 0 | F25: 0 | G25: 0 | H25: 110
A26: google / cpc | B26: 44044 | C26: 1355 | D26: 0.85126799 | E26: 11712 | F26: 1505 | G26: 105.19333 | H26: 1873
A27: google / cpc | B27: 44045 | C27: 1426 | D27: 0.8490566 | E27: 12174 | F27: 1548 | G27: 107.60315 | H27: 1957
... A45: google / cpc | B45: 44063 | C45: 1400 | D45: 0.85459352 | E45: 13840 | F45: 1494 | G45: 123.75542 | H45: 1977

Sheet Report
A1: источник | B1: дата | C1: расход | D1: расход с НДС | E1: показы | F1: клики | G1: CTR | H1: CPC | I1: Доход(в источнике нет, рисую от болды) | J1: CR | K1: ROMI | L1: CPA | M1: RPC | N1: % отказа
A2: =LIB!A16 -> google / cpc | B2: =LIB!B16 -> 44034 | C2: =LIB!G16 -> 0 | D2: =C2*1.2 -> 0 | E2: =LIB!E16 -> 0 | F2: =LIB!F16 -> 0 | G2: =F2/E2 -> #DIV/0! | H2: =D2/F2 -> #DIV/0! | I2: =D2*1.55 -> 0 | K2: =I2/D2 -> #DIV/0! | M2: =I2/F2 -> #DIV/0! | N2: =LIB!D16 -> 0.94444444
A3: =LIB!A17 -> google / cpc | B3: =LIB!B17 -> 44035 | C3: =LIB!G17 -> 77.189121 | D3: =C3*1.2 -> 92.626945 | E3: =LIB!E17 -> 8288 | F3: =LIB!F17 -> 978 | G3: =F3/E3 -> 0.11800193 | H3: =D3/F3 -> 0.094710578 | I3: =D3*1.55 -> 143.57177 | K3: =I3/D3 -> 1.55 | M3: =I3/F3 -> 0.1468014 | N3: =LIB!D17 -> 0.86395233
A4: =LIB!A18 -> google / cpc | B4: =LIB!B18 -> 44036 | C4: =LIB!G18 -> 135.71073 | D4: =C4*1.2 -> 162.85288 | E4: =LIB!E18 -> 13924 | F4: =LIB!F18 -> 1864 | G4: =F4/E4 -> 0.13386958 | H4: =D4/F4 -> 0.087367424 | I4: =D4*1.55 -> 252.42196 | K4: =I4/D4 -> 1.55 | M4: =I4/F4 -> 0.13541951 | N4: =LIB!D18 -> 0.84430804
A5: =LIB!A19 -> google / cpc | B5: =LIB!B19 -> 44037 | C5: =LIB!G19 -> 147.0287 | D5: =C5*1.2 -> 176.43444 | E5: =LIB!E19 -> 13748 | F5: =LIB!F19 -> 1783 | G5: =F5/E5 -> 0.12969159 | H5: =D5/F5 -> 0.098953695 | I5: =D5*1.55 -> 273.47338 | K5: =I5/D5 -> 1.55 | M5: =I5/F5 -> 0.15337823 | N5: =LIB!D19 -> 0.86096866
A6: =LIB!A20 -> google / cpc | B6: =LIB!B20 -> 44038 | C6: =LIB!G20 -> 51.349739 | D6: =C6*1.2 -> 61.619687 | E6: =LIB!E20 -> 5028 | F6: =LIB!F20 -> 673 | G6: =F6/E6 -> 0.13385044 | H6: =D6/F6 -> 0.091559713 | I6: =D6*1.24 -> 76.408412 | K6: =I6/D6 -> 1.24 | M6: =I6/F6 -> 0.11353404 | N6: =LIB!D20 -> 0.86376404
A7: =LIB!A21 -> google / cpc | B7: =LIB!B21 -> 44039 | C7: =LIB!G21 -> 0 | D7: =C7*1.2 -> 0 | E7: =LIB!E21 -> 0 | F7: =LIB!F21 -> 0 | G7: =F7/E7 -> #DIV/0! | H7: =D7/F7 -> #DIV/0! | I7: =D7*1.53 -> 0 | K7: =I7/D7 -> #DIV/0! | M7: =I7/F7 -> #DIV/0! | N7: =LIB!D21 -> 0.8974359
A8: =LIB!A22 -> google / cpc | B8: =LIB!B22 -> 44040 | C8: =LIB!G22 -> 0 | D8: =C8*1.2 -> 0 | E8: =LIB!E22 -> 0 | F8: =LIB!F22 -> 0 | G8: =F8/E8 -> #DIV/0! | H8: =D8/F8 -> #DIV/0! | I8: =D8*1.55 -> 0 | K8: =I8/D8 -> #DIV/0! | M8: =I8/F8 -> #DIV/0! | N8: =LIB!D22 -> 0.97222222
A9: =LIB!A23 -> google / cpc | B9: =LIB!B23 -> 44041 | C9: =LIB!G23 -> 0 | D9: =C9*1.2 -> 0 | E9: =LIB!E23 -> 0 | F9: =LIB!F23 -> 0 | G9: =F9/E9 -> #DIV/0! | H9: =D9/F9 -> #DIV/0! | I9: =D9*1.55 -> 0 | K9: =I9/D9 -> #DIV/0! | M9: =I9/F9 -> #DIV/0! | N9: =LIB!D23 -> 0.95652174
A10: =LIB!A24 -> google / cpc | B10: =LIB!B24 -> 44042 | C10: =LIB!G24 -> 0 | D10: =C10*1.2 -> 0 | E10: =LIB!E24 -> 0 | F10: =LIB!F24 -> 0 | G10: =F10/E10 -> #DIV/0! | H10: =D10/F10 -> #DIV/0! | I10: =D10*1.55 -> 0 | K10: =I10/D10 -> #DIV/0! | M10: =I10/F10 -> #DIV/0! | N10: =LIB!D24 -> 0.95238095
A11: =LIB!A25 -> google / cpc | B11: =LIB!B25 -> 44043 | C11: =LIB!G25 -> 0 | D11: =C11*1.2 -> 0 | E11: =LIB!E25 -> 0 | F11: =LIB!F25 -> 0 | G11: =F11/E11 -> #DIV/0! | H11: =D11/F11 -> #DIV/0! | I11: =D11*1.55 -> 0 | K11: =I11/D11 -> #DIV/0! | M11: =I11/F11 -> #DIV/0! | N11: =LIB!D25 -> 0.825
A12: =LIB!A26 -> google / cpc | B12: =LIB!B26 -> 44044 | C12: =LIB!G26 -> 105.19333 | D12: =C12*1.2 -> 126.232 | E12: =LIB!E26 -> 11712 | F12: =LIB!F26 -> 1505 | G12: =F12/E12 -> 0.12850068 | H12: =D12/F12 -> 0.083875084 | I12: =D12*1.55 -> 195.6596 | K12: =I12/D12 -> 1.55 | M12: =I12/F12 -> 0.13000638 | N12: =LIB!D26 -> 0.85126799
A13: =LIB!A27 -> google / cpc | B13: =LIB!B27 -> 44045 | C13: =LIB!G27 -> 107.60315 | D13: =C13*1.2 -> 129.12378 | E13: =LIB!E27 -> 12174 | F13: =LIB!F27 -> 1548 | G13: =F13/E13 -> 0.12715623 | H13: =D13/F13 -> 0.083413295 | I13: =D13*1.55 -> 200.14186 | K13: =I13/D13 -> 1.55 | M13: =I13/F13 -> 0.12929061 | N13: =LIB!D27 -> 0.8490566
A14: =LIB!A28 -> google / cpc | B14: =LIB!B28 -> 44046 | C14: =LIB!G28 -> 112.07402 | D14: =C14*1.2 -> 134.48882 | E14: =LIB!E28 -> 12207 | F14: =LIB!F28 -> 1573 | G14: =F14/E14 -> 0.12886049 | H14: =D14/F14 -> 0.085498299 | I14: =D14*1.55 -> 208.45768 | K14: =I14/D14 -> 1.55 | M14: =I14/F14 -> 0.13252236 | N14: =LIB!D28 -> 0.84007707
A15: =LIB!A29 -> google / cpc | B15: =LIB!B29 -> 44047 | C15: =LIB!G29 -> 124.19425 | D15: =C15*1.2 -> 149.0331 | E15: =LIB!E29 -> 13118 | F15: =LIB!F29 -> 1690 | G15: =F15/E15 -> 0.12883061 | H15: =D15/F15 -> 0.088185269 | I15: =D15*1.55 -> 231.00131 | K15: =I15/D15 -> 1.55 | M15: =I15/F15 -> 0.13668717 | N15: =LIB!D29 -> 0.84968079
A16: =LIB!A30 -> google / cpc | B16: =LIB!B30 -> 44048 | C16: =LIB!G30 -> 132.07572 | D16: =C16*1.2 -> 158.49086 | E16: =LIB!E30 -> 13344 | F16: =LIB!F30 -> 1699 | G16: =F16/E16 -> 0.12732314 | H16: =D16/F16 -> 0.093284791 | I16: =D16*1.55 -> 245.66083 | K16: =I16/D16 -> 1.55 | M16: =I16/F16 -> 0.14459143 | N16: =LIB!D30 -> 0.85602879
A17: =LIB!A31 -> google / cpc | B17: =LIB!B31 -> 44049 | C17: =LIB!G31 -> 126.86468 | D17: =C17*1.2 -> 152.23762 | E17: =LIB!E31 -> 14124 | F17: =LIB!F31 -> 1821 | G17: =F17/E17 -> 0.12892948 | H17: =D17/F17 -> 0.08360111 | I17: =D17*1.15 -> 175.07326 | K17: =I17/D17 -> 1.15 | M17: =I17/F17 -> 0.096141276 | N17: =LIB!D31 -> 0.85667396
A18: =LIB!A32 -> google / cpc | B18: =LIB!B32 -> 44050 | C18: =LIB!G32 -> 128.06479 | D18: =C18*1.2 -> 153.67775 | E18: =LIB!E32 -> 14432 | F18: =LIB!F32 -> 1656 | G18: =F18/E18 -> 0.11474501 | H18: =D18/F18 -> 0.092800575 | I18: =D18*1.33 -> 204.39141 | K18: =I18/D18 -> 1.33 | M18: =I18/F18 -> 0.12342477 | N18: =LIB!D32 -> 0.85722855
A19: =LIB!A33 -> google / cpc | B19: =LIB!B33 -> 44051 | C19: =LIB!G33 -> 129.2416 | D19: =C19*1.2 -> 155.08992 | E19: =LIB!E33 -> 13155 | F19: =LIB!F33 -> 1621 | G19: =F19/E19 -> 0.12322311 | H19: =D19/F19 -> 0.095675458 | I19: =D19*1.3544 -> 210.05378 | K19: =I19/D19 -> 1.3544 | M19: =I19/F19 -> 0.12958284 | N19: =LIB!D33 -> 0.86735941
A20: =LIB!A34 -> google / cpc | B20: =LIB!B34 -> 44052 | C20: =LIB!G34 -> 112.43128 | D20: =C20*1.2 -> 134.91754 | E20: =LIB!E34 -> 12821 | F20: =LIB!F34 -> 1555 | G20: =F20/E20 -> 0.12128539 | H20: =D20/F20 -> 0.086763692 | I20: =D20*1.55 -> 209.12219 | K20: =I20/D20 -> 1.55 | M20: =I20/F20 -> 0.13448372 | N20: =LIB!D34 -> 0.85350318
A21: =LIB!A35 -> google / cpc | B21: =LIB!B35 -> 44053 | C21: =LIB!G35 -> 114.1629 | D21: =C21*1.2 -> 136.99548 | E21: =LIB!E35 -> 13595 | F21: =LIB!F35 -> 1537 | G21: =F21/E21 -> 0.11305627 | H21: =D21/F21 -> 0.089131739 | I21: =D21*1.5545 -> 212.95948 | K21: =I21/D21 -> 1.5545 | M21: =I21/F21 -> 0.13855529 | N21: =LIB!D35 -> 0.85158782
A22: =LIB!A36 -> google / cpc | B22: =LIB!B36 -> 44054 | C22: =LIB!G36 -> 122.74724 | D22: =C22*1.2 -> 147.29669 | E22: =LIB!E36 -> 14359 | F22: =LIB!F36 -> 1618 | G22: =F22/E22 -> 0.11268194 | H22: =D22/F22 -> 0.091036272 | I22: =D22*1.55 -> 228.30987 | K22: =I22/D22 -> 1.55 | M22: =I22/F22 -> 0.14110622 | N22: =LIB!D36 -> 0.84454041
A23: =LIB!A37 -> google / cpc | B23: =LIB!B37 -> 44055 | C23: =LIB!G37 -> 126.45108 | D23: =C23*1.2 -> 151.74129 | E23: =LIB!E37 -> 13699 | F23: =LIB!F37 -> 1610 | G23: =F23/E23 -> 0.11752683 | H23: =D23/F23 -> 0.094249248 | I23: =D23*1.55 -> 235.199 | K23: =I23/D23 -> 1.55 | M23: =I23/F23 -> 0.14608634 | N23: =LIB!D37 -> 0.85285101
A24: =LIB!A38 -> google / cpc | B24: =LIB!B38 -> 44056 | C24: =LIB!G38 -> 121.53177 | D24: =C24*1.2 -> 145.83813 | E24: =LIB!E38 -> 13655 | F24: =LIB!F38 -> 1546 | G24: =F24/E24 -> 0.1132186 | H24: =D24/F24 -> 0.094332555 | I24: =D24*1.55 -> 226.0491 | K24: =I24/D24 -> 1.55 | M24: =I24/F24 -> 0.14621546 | N24: =LIB!D38 -> 0.85934489
A25: =LIB!A39 -> google / cpc | B25: =LIB!B39 -> 44057 | C25: =LIB!G39 -> 119.68102 | D25: =C25*1.2 -> 143.61723 | E25: =LIB!E39 -> 12870 | F25: =LIB!F39 -> 1489 | G25: =F25/E25 -> 0.11569542 | H25: =D25/F25 -> 0.096452134 | I25: =D25*1.55 -> 222.6067 | K25: =I25/D25 -> 1.55 | M25: =I25/F25 -> 0.14950081 | N25: =LIB!D39 -> 0.838
A26: =LIB!A40 -> google / cpc | B26: =LIB!B40 -> 44058 | C26: =LIB!G40 -> 106.66585 | D26: =C26*1.2 -> 127.99902 | E26: =LIB!E40 -> 11154 | F26: =LIB!F40 -> 1358 | G26: =F26/E26 -> 0.12175004 | H26: =D26/F26 -> 0.094255535 | I26: =D26*1.11 -> 142.07891 | K26: =I26/D26 -> 1.11 | M26: =I26/F26 -> 0.10462364 | N26: =LIB!D40 -> 0.84210526
A27: =LIB!A41 -> google / cpc | B27: =LIB!B41 -> 44059 | C27: =LIB!G41 -> 124.69725 | D27: =C27*1.2 -> 149.6367 | E27: =LIB!E41 -> 12713 | F27: =LIB!F41 -> 1495 | G27: =F27/E27 -> 0.11759616 | H27: =D27/F27 -> 0.10009144 | I27: =D27*1.22 -> 182.55677 | K27: =I27/D27 -> 1.22 | M27: =I27/F27 -> 0.12211155 | N27: =LIB!D41 -> 0.86473755
A28: =LIB!A42 -> google / cpc | B28: =LIB!B42 -> 44060 | C28: =LIB!G42 -> 104.1103 | D28: =C28*1.2 -> 124.93236 | E28: =LIB!E42 -> 12847 | F28: =LIB!F42 -> 1409 | G28: =F28/E28 -> 0.10967541 | H28: =D28/F28 -> 0.088667396 | I28: =D28*1.66 -> 207.38772 | K28: =I28/D28 -> 1.66 | M28: =I28/F28 -> 0.14718788 | N28: =LIB!D42 -> 0.86383285
A29: =LIB!A43 -> google / cpc | B29: =LIB!B43 -> 44061 | C29: =LIB!G43 -> 117.3281 | D29: =C29*1.2 -> 140.79372 | E29: =LIB!E43 -> 13187 | F29: =LIB!F43 -> 1518 | G29: =F29/E29 -> 0.11511337 | H29: =D29/F29 -> 0.092749486 | I29: =D29*1.55 -> 218.23027 | K29: =I29/D29 -> 1.55 | M29: =I29/F29 -> 0.1437617 | N29: =LIB!D43 -> 0.84089415
A30: =LIB!A44 -> google / cpc | B30: =LIB!B44 -> 44062 | C30: =LIB!G44 -> 118.50477 | D30: =C30*1.2 -> 142.20572 | E30: =LIB!E44 -> 13079 | F30: =LIB!F44 -> 1519 | G30: =F30/E30 -> 0.11614038 | H30: =D30/F30 -> 0.093617986 | I30: =D30*3 -> 426.61716 | K30: =I30/D30 -> 3 | M30: =I30/F30 -> 0.28085396 | N30: =LIB!D44 -> 0.84428384
A31: =LIB!A45 -> google / cpc | B31: =LIB!B45 -> 44063 | C31: =LIB!G45 -> 123.75542 | D31: =C31*1.2 -> 148.5065 | E31: =LIB!E45 -> 13840 | F31: =LIB!F45 -> 1494 | G31: =F31/E31 -> 0.10794798 | H31: =D31/F31 -> 0.099401944 | I31: =D31*2 -> 297.01301 | K31: =I31/D31 -> 2 | M31: =I31/F31 -> 0.19880389 | N31: =LIB!D45 -> 0.85459352
A32: =LIB!A46 | B32: =LIB!B46 | N32: =LIB!D46
A33: =LIB!A47 | B33: =LIB!B47
B34: =LIB!B48
B35: =LIB!B49
B36: =LIB!B50
B37: =LIB!B51
B38: =LIB!B52
B39: =LIB!B53
B40: =LIB!B54
...
